Traceback (most recent call last):
  File "C:\Users\cassi\anaconda3\envs\rclib\Lib\site-packages\jupyter_cache\executors\utils.py", line 58, in single_nb_execution
    executenb(
  File "C:\Users\cassi\anaconda3\envs\rclib\Lib\site-packages\nbclient\client.py", line 1314, in execute
    return NotebookClient(nb=nb, resources=resources, km=km, **kwargs).execute()
           ^^^^^^^^^^^^^^^^^^^^^^^^^^^^^^^^^^^^^^^^^^^^^^^^^^^^^^^^^^^^^^^^^^^^^
  File "C:\Users\cassi\anaconda3\envs\rclib\Lib\site-packages\jupyter_core\utils\__init__.py", line 165, in wrapped
    return loop.run_until_complete(inner)
           ^^^^^^^^^^^^^^^^^^^^^^^^^^^^^^
  File "C:\Users\cassi\anaconda3\envs\rclib\Lib\asyncio\base_events.py", line 687, in run_until_complete
    return future.result()
           ^^^^^^^^^^^^^^^
  File "C:\Users\cassi\anaconda3\envs\rclib\Lib\site-packages\nbclient\client.py", line 709, in async_execute
    await self.async_execute_cell(
  File "C:\Users\cassi\anaconda3\envs\rclib\Lib\site-packages\nbclient\client.py", line 1062, in async_execute_cell
    await self._check_raise_for_error(cell, cell_index, exec_reply)
  File "C:\Users\cassi\anaconda3\envs\rclib\Lib\site-packages\nbclient\client.py", line 918, in _check_raise_for_error
    raise CellExecutionError.from_cell_and_msg(cell, exec_reply_content)
nbclient.exceptions.CellExecutionError: An error occurred while executing the following cell:
------------------
import sympy as sym
f = sym.Function('f')
y = sym.Function('y')
n = sym.symbols(r'\alpha')
f = y(n)-2*y(n-1/sym.pi)-5*y(n-2)
glue("sym_eq", sym.rsolve(f,y(n),[1,4]))
------------------


[1;31m---------------------------------------------------------------------------[0m
[1;31mModuleNotFoundError[0m                       Traceback (most recent call last)
Cell [1;32mIn[7], line 1[0m
[1;32m----> 1[0m [38;5;28;01mimport[39;00m [38;5;21;01msympy[39;00m [38;5;28;01mas[39;00m [38;5;21;01msym[39;00m
[0;32m      2[0m f [38;5;241m=[39m sym[38;5;241m.[39mFunction([38;5;124m'[39m[38;5;124mf[39m[38;5;124m'[39m)
[0;32m      3[0m y [38;5;241m=[39m sym[38;5;241m.[39mFunction([38;5;124m'[39m[38;5;124my[39m[38;5;124m'[39m)

[1;31mModuleNotFoundError[0m: No module named 'sympy'

